Workbook

Sheet EEE
A1: BVRIT HYDERABAD College of Engineering for Women (WH)
A2: Rajiv Gandhi Nagar, Bachupally, Hyderabad-500090
A3: III B.TECH. I SEM (R22) NOMINAL ROLLS
A4: 2022 BATCH – FOR THE ACADEMIC YEAR 2023-2024
A5: Branch: EEE | G5: Date: 10.08.2024
A6: S.No. | B6: Hall Ticket No. | C6: Name of the Candidate | E6: S.No. | F6: Hall Ticket No. | G6: Name of the Candidate
A7: 1 | B7: 22WH1A0201 | C7: POLKAM LAHARI | E7: 31 | F7: 22WH1A0232 | G7: KONDAPARTHI MAHIMA
A8: 2 | B8: 22WH1A0202 | C8: RATHOD KEERTHI | E8: 32 | F8: 22WH1A0233 | G8: LANDE NIHARIKA
A9: 3 | B9: 22WH1A0203 | C9: MORAMPUDI CHATURYA CHOWDARY | E9: 33 | F9: 22WH1A0234 | G9: KADARLA AISHWARYA
A10: 4 | B10: 22WH1A0204 | C10: BUDUTHA MAMATHA | E10: 34 | F10: 22WH1A0235 | G10: BANOTHU DEEPIKA
A11: 5 | B11: 22WH1A0205 | C11: SRI PRIYA RATHOD | E11: 35 | F11: 22WH1A0236 | G11: CH.NAVYA SRI
A12: 6 | B12: 22WH1A0206 | C12: DAKURI APARANJANI REDDY | E12: 36 | F12: 22WH1A0237 | G12: MADDUR NIKHITHA
A13: 7 | B13: 22WH1A0207 | C13: BURRI LAXMI PRASANNA | E13: 37 | F13: 22WH1A0238 | G13: KOTTE SADHVI SREE
A14: 8 | B14: 22WH1A0208 | C14: GUNDE SREEJA | E14: 38 | F14: 22WH1A0239 | G14: CHINNAVULA SUSHMITHA
A15: 9 | B15: 22WH1A0209 | C15: SRIGIRI ADVAITHA | E15: 39 | F15: 22WH1A0240 | G15: DIBBA MOUNIKA
A16: 10 | B16: 22WH1A0210 | C16: GODUMAGAMA BHAVANA | E16: 40 | F16: 22WH1A0241 | G16: ALUSA SRIJA
A17: 11 | B17: 22WH1A0211 | C17: RAJAPURAM GAYATHRI | E17: 41 | F17: 22WH1A0242 | G17: MACHA SHIVA DEEPIKA
A18: 12 | B18: 22WH1A0212 | C18: JERRIPOTHULA BHAVYA SREE | E18: 42 | F18: 22WH1A0243 | G18: TEJAVATH MANASA
... A42: 64 | B42: 23WH5A0216 | C42: CH. MANASA | E42: 69 | F42: 23WH5A0221 | G42: S. HARINI
A43: 65 | B43: 23WH5A0217 | C43: G. SAI KEERTHANA
B46: Note: | C46: 22WH1A0226 Detained in I-I due to shortage of attendance for the A.Y. 2022-23
C47: 22WH1A0251 Detained in I-I due to shortage of attendance for the A.Y. 2022-23
C48: 22WH1A0250 Detained in I-II due to shortage of attendance for the A.Y. 2022-23
C49: 21WH1A0248 Re-Admitted in II-I for the A.Y. 2023-24
C50: 21WH1A0248 Discontinued(taken T.C) in II-II for the A.Y. 2023-24
B54: Examinations Incharge | G54: Principal

Sheet ECE A
A1: BVRIT HYDERABAD College of Engineering for Women (WH)
A2: Rajiv Gandhi Nagar, Bachupally, Hyderabad-500090
A3: III B.TECH. I SEM (R22) NOMINAL ROLLS
A4: 2022 BATCH – FOR THE ACADEMIC YEAR 2023-2024
A5: Branch: ECE A | G5: Date: 10.08.2024
A6: S.No. | B6: Hall Ticket No. | C6: Name of the Candidate | E6: S.No. | F6: Hall Ticket No. | G6: Name of the Candidate
A7: 1 | B7: 21WH1A0483 | C7: S.PAVANI | E7: 33 | F7: 22WH1A0432 | G7: RAVOORI LAKSHMI TULASI
A8: 2 | B8: 22WH1A0401 | C8: MADDIREDDY SAI VIDHITHA | E8: 34 | F8: 22WH1A0433 | G8: CHINTA VIDYADHARI
A9: 3 | B9: 22WH1A0402 | C9: BUJJOLLU NIKITHA | E9: 35 | F9: 22WH1A0434 | G9: KONAPARTHI HARIKA
A10: 4 | B10: 22WH1A0403 | C10: BUSAPUR SUBIDHA | E10: 36 | F10: 22WH1A0435 | G10: DEVOLLA VENNELA
A11: 5 | B11: 22WH1A0404 | C11: KONDA ROHITHA VARMA | E11: 37 | F11: 22WH1A0436 | G11: DESHPEDDI SRINIJA
A12: 6 | B12: 22WH1A0405 | C12: MADUPALLY SRAVANI | E12: 38 | F12: 22WH1A0437 | G12: AKKALA HIMAVARSHINI
A13: 7 | B13: 22WH1A0406 | C13: RUKMINI CHAKRAVARTHULA | E13: 39 | F13: 22WH1A0438 | G13: JANGLI SHREEHA
A14: 8 | B14: 22WH1A0407 | C14: DODDAPANENI TEJOPRAYUKTHA | E14: 40 | F14: 22WH1A0439 | G14: KURASA LAKSHMI DURGA
A15: 9 | B15: 22WH1A0408 | C15: BEGARI SNEHA | E15: 41 | F15: 22WH1A0440 | G15: S PARVEEN
A16: 10 | B16: 22WH1A0409 | C16: GADDAM SANJANA | E16: 42 | F16: 22WH1A0441 | G16: G AVANTHIKA
A17: 11 | B17: 22WH1A0410 | C17: DHATRI SRI SINGU | E17: 43 | F17: 22WH1A0442 | G17: BH.RADHAMRUTHA
A18: 12 | B18: 22WH1A0411 | C18: UPPAMAGULURI VANAJA | E18: 44 | F18: 22WH1A0443 | G18: APPILETI NAVYA SRI
... A37: 31 | B37: 22WH1A0430 | C37: KALLURI HANSIKA | E37: 63 | F37: 22WH1A0464 | G37: ODHURI RAJA RAJESWARI LALITA AMBICA
A38: 32 | B38: 22WH1A0431 | C38: GUNDREDIPALLY SARAYU
A42: 64 | B42: 23WH5A0401 | C42: CHEEKOTI RITHIKA | E42: 67 | F42: 23WH5A0404 | G42: MOTHE SATHWIKA
A43: 65 | B43: 23WH5A0402 | C43: GUDIPUDI MEENAKSHI | E43: 68 | F43: 23WH5A0405 | G43: JADDU TEJOMAYI
A44: 66 | B44: 23WH5A0403 | C44: GUNDETI VIJAYALAKSHMI | E44: 69 | F44: 23WH5A0406 | G44: CHIRRAM SARAYU
B47: Note: | C47: 22WH1A0458 Detained in I-II due to shortage of attendance for the A.Y. 2022-23
C48: 21WH1A0483 Re-joined in 2-2 for the A.Y. 2023-24
C49: 22WH1A0463 Detained in II-II due to shortage of attendance for the A.Y. 2023-24
B52: Examinations Incharge | G52: Principal

Sheet ECE B
A1: BVRIT HYDERABAD College of Engineering for Women (WH)
A2: Rajiv Gandhi Nagar, Bachupally, Hyderabad-500090
A3: III B.TECH. I SEM (R22) NOMINAL ROLLS
A4: 2022 BATCH – FOR THE ACADEMIC YEAR 2023-2024
A5: Branch: ECE B | G5: Date: 10.08.2024
A6: S.No. | B6: Hall Ticket No. | C6: Name of the Candidate | E6: S.No. | F6: Hall Ticket No. | G6: Name of the Candidate
A7: 1 | B7: 22WH1A0465 | C7: KANDULA SRI NITHYA | E7: 33 | F7: 22WH1A0497 | G7: KORITALA GEETHIKA CHOWDARY
A8: 2 | B8: 22WH1A0466 | C8: SINDHE PAVANI | E8: 34 | F8: 22WH1A0498 | G8: PAMU JHANSI
A9: 3 | B9: 22WH1A0467 | C9: PECHHITTI JAYASRI | E9: 35 | F9: 22WH1A0499 | G9: KUNCHALA SUSMITHA
A10: 4 | B10: 22WH1A0468 | C10: MARINENI LAKSHMIJYOTHIRMAI | E10: 36 | F10: 22WH1A04A0 | G10: CHIPPADA JYOTHIRMAYEE
A11: 5 | B11: 22WH1A0469 | C11: DASARI BHANU SAI GOWRI SHANMUKHI | E11: 37 | F11: 22WH1A04A1 | G11: MAKIREDDY CHANDINI
A12: 6 | B12: 22WH1A0470 | C12: PRATHI SREE PRIYA | E12: 38 | F12: 22WH1A04A2 | G12: GARINAPALLY SANJANA
A13: 7 | B13: 22WH1A0471 | C13: CHALLA HEMAMSHITHA REDDY | E13: 39 | F13: 22WH1A04A3 | G13: DASARI SRI SAI SANTHOSHI LAHARI
A14: 8 | B14: 22WH1A0472 | C14: BODA INDHU PRIYA | E14: 40 | F14: 22WH1A04A4 | G14: GAJAM SHIREESHA
A15: 9 | B15: 22WH1A0473 | C15: P.SRIVANI | E15: 41 | F15: 22WH1A04A5 | G15: SARAQATOON
A16: 10 | B16: 22WH1A0474 | C16: POOJITHA GARREPALLI | E16: 42 | F16: 22WH1A04A6 | G16: S.ANJANI SUTA
A17: 11 | B17: 22WH1A0475 | C17: VENNELI KAVITHA | E17: 43 | F17: 22WH1A04A7 | G17: ARLA JEEVANA JYOTI
A18: 12 | B18: 22WH1A0476 | C18: MANCHIKANTI SAI VARSHINI | E18: 44 | F18: 22WH1A04A8 | G18: TEKI DURGA DEVI
... A43: 67 | B43: 23WH5A0409 | C43: KANAKAM SINDU SREE | E43: 70 | F43: 23WH5A0413 | G43: YADAVALLI LAKSHMI TIRUPATAMMA
B47: Note: | C47: 23WH5A0411 Detained in II-II due to shortage of attendance for the A.Y. 2023-24
B52: Examinations Incharge | G52: Principal

Sheet CSE A
A1: BVRIT HYDERABAD College of Engineering for Women (WH)
A2: Rajiv Gandhi Nagar, Bachupally, Hyderabad-500090
A3: III B.TECH. I SEM (R22) NOMINAL ROLLS
A4: 2022 BATCH – FOR THE ACADEMIC YEAR 2023-2024
A5: Branch: CSE A | G5: Date: 10.08.2024
A6: S.No. | B6: Hall Ticket No. | C6: Name of the Candidate | E6: S.No. | F6: Hall Ticket No. | G6: Name of the Candidate
A7: 1 | B7: 22WH1A0501 | C7: REDDY SAI HARSHITHA | E7: 34 | F7: 22WH1A0534 | G7: GUNTUKA AMULYA
A8: 2 | B8: 22WH1A0502 | C8: CHIRRA DEEPTHI | E8: 35 | F8: 22WH1A0535 | G8: JANGAM MANASA
A9: 3 | B9: 22WH1A0503 | C9: CHINTAPATLA ANUSHA | E9: 36 | F9: 22WH1A0536 | G9: SURAM SHREYA REDDY
A10: 4 | B10: 22WH1A0504 | C10: CHERUKURI TARUNI RAO | E10: 37 | F10: 22WH1A0537 | G10: P DEEPTHI
A11: 5 | B11: 22WH1A0505 | C11: BOYA SURABHI | E11: 38 | F11: 22WH1A0538 | G11: SHANKAR PRANUSHA
A12: 6 | B12: 22WH1A0506 | C12: SHAARIYA ALI | E12: 39 | F12: 22WH1A0539 | G12: DATLA NAYANA
A13: 7 | B13: 22WH1A0507 | C13: MALLELA SUPRIYA | E13: 40 | F13: 22WH1A0540 | G13: PRANJAL MUNDADA
A14: 8 | B14: 22WH1A0508 | C14: MUNTHA KAVYA | E14: 41 | F14: 22WH1A0541 | G14: MOPARTHI SONIA
A15: 9 | B15: 22WH1A0509 | C15: PATLOLLA KUSHI REDDY | E15: 42 | F15: 22WH1A0542 | G15: GUNDA SIREE
A16: 10 | B16: 22WH1A0510 | C16: CHINNAMGARI AKSHAYA | E16: 43 | F16: 22WH1A0543 | G16: PIPPALLA KEERTHI PRASANNA
A17: 11 | B17: 22WH1A0511 | C17: ITTA SARAH SAMYUKTHA | E17: 44 | F17: 22WH1A0544 | G17: ERELLI USHASREE
A18: 12 | B18: 22WH1A0512 | C18: R.K.LASYA | E18: 45 | F18: 22WH1A0545 | G18: CHARUGUNDLA DEVI SRI BHUVANA
... A38: 32 | B38: 22WH1A0532 | C38: D SNEHITHA | E38: 65 | F38: 22WH1A0565 | G38: YERUKALA POOJITHA
A39: 33 | B39: 22WH1A0533 | C39: VEMULA LAKSHMI SAHITHI CHOWDARY
A43: 66 | B43: 23WH5A0501 | C43: GORINTA SRAVANI | E43: 69 | F43: 23WH5A0504 | G43: BOGARI NIDARKAR NANDINI
A44: 67 | B44: 23WH5A0502 | C44: MACCHA ABHINAYA | E44: 70 | F44: 23WH5A0505 | G44: GAJULA SNEHITHA
A45: 68 | B45: 23WH5A0503 | C45: KOKKONDA REKHA | E45: 71 | F45: 23WH5A0506 | G45: MANCHALA AKSHAYA
B52: Examinations Incharge | G52: Principal

Sheet CSE B
A1: BVRIT HYDERABAD College of Engineering for Women (WH)
A2: Rajiv Gandhi Nagar, Bachupally, Hyderabad-500090
A3: III B.TECH. I SEM (R22) NOMINAL ROLLS
A4: 2022 BATCH – FOR THE ACADEMIC YEAR 2023-2024
A5: Branch: CSE B | G5: Date: 10.08.2024
A6: S.No. | B6: Hall Ticket No. | C6: Name of the Candidate | E6: S.No. | F6: Hall Ticket No. | G6: Name of the Candidate
A7: 1 | B7: 22WH1A0566 | C7: KARRI SURYA MOUNIKA | E7: 32 | F7: 22WH1A0598 | G7: GADDAM SRI BHAVANI
A8: 2 | B8: 22WH1A0567 | C8: C SAI VIDYA | E8: 33 | F8: 22WH1A0599 | G8: CHAKKIRALA HARSHITHA
A9: 3 | B9: 22WH1A0568 | C9: M.SIVAPRIYA | E9: 34 | F9: 22WH1A05A0 | G9: VADDUL AMULYA
A10: 4 | B10: 22WH1A0569 | C10: SINGAMSETTI BALA JAYA SRI | E10: 35 | F10: 22WH1A05A1 | G10: P.SANANDHA
A11: 5 | B11: 22WH1A0570 | C11: SINGAMALA MOKSHITHA REDDY | E11: 36 | F11: 22WH1A05A2 | G11: ISUKAPALLI THANVI SHREYA
A12: 6 | B12: 22WH1A0571 | C12: UPADHYAY VAISHNAVI | E12: 37 | F12: 22WH1A05A3 | G12: B UMA MAHESHWARI
A13: 7 | B13: 22WH1A0572 | C13: PAGADALA NIKITHA | E13: 38 | F13: 22WH1A05A4 | G13: MALLEPALLY YAMINI
A14: 8 | B14: 22WH1A0573 | C14: BANOTHU SRINIDHI | E14: 39 | F14: 22WH1A05A5 | G14: KOLLI SRI NAGALAKSHMI TRIVENI
A15: 9 | B15: 22WH1A0574 | C15: YELURI INDHU | E15: 40 | F15: 22WH1A05A6 | G15: CHANDALURI OMKARESWARI MADHU SUPRAJA
A16: 10 | B16: 22WH1A0575 | C16: VARPULA VIGNA | E16: 41 | F16: 22WH1A05A7 | G16: CHILUMOJU SAHANA
A17: 11 | B17: 22WH1A0577 | C17: NAVUDURI LAKSHMI NEEHARIKA | E17: 42 | F17: 22WH1A05A8 | G17: KARANAM HIMA VARSHA
A18: 12 | B18: 22WH1A0578 | C18: VANKADARA GEETA GAYATRI | E18: 43 | F18: 22WH1A05A9 | G18: KOTTE BHAVANI
... A45: 65 | B45: 23WH5A0509 | C45: RAVULA ABHINAYA | E45: 68 | F45: 23WH5A0512 | G45: KOMMU ASHWITHA
B47: Note: | C47: 22WH1A0576 Detained in II-II due to shortage of attendance for the A.Y. 2023-24
C48: 22WH1A05C5 Detained in II-II due to shortage of attendance for the A.Y. 2023-24
B52: Examinations Incharge | G52: Principal

Sheet CSE C
A1: BVRIT HYDERABAD College of Engineering for Women (WH)
A2: Rajiv Gandhi Nagar, Bachupally, Hyderabad-500090
A3: III B.TECH. I SEM (R22) NOMINAL ROLLS
A4: 2022 BATCH – FOR THE ACADEMIC YEAR 2023-2024
A5: Branch: CSE C | G5: Date: 10.08.2024
A6: S.No. | B6: Hall Ticket No. | C6: Name of the Candidate | E6: S.No. | F6: Hall Ticket No. | G6: Name of the Candidate
A7: 1 | B7: 22WH1A05D0 | C7: BANDARU SMRITI RAO | E7: 33 | F7: 22WH1A05G2 | G7: AFSHA ZABEEN
A8: 2 | B8: 22WH1A05D1 | C8: ARRAM DEEPINI | E8: 34 | F8: 22WH1A05G3 | G8: RASHI DESHMUKH
A9: 3 | B9: 22WH1A05D2 | C9: GUGULOTHU SAI SARASWATHI | E9: 35 | F9: 22WH1A05G4 | G9: KOSARAJU JOSHITHA
A10: 4 | B10: 22WH1A05D3 | C10: VEMULA KYATHI LAXMI | E10: 36 | F10: 22WH1A05G5 | G10: BACHHALI YAMINI
A11: 5 | B11: 22WH1A05D4 | C11: THOLETI ANJALI | E11: 37 | F11: 22WH1A05G6 | G11: KHYYATI VEGIRAJU
A12: 6 | B12: 22WH1A05D5 | C12: GADDIPATI VEDASRI LAKSHMI | E12: 38 | F12: 22WH1A05G7 | G12: UNGARALA VASUDHA
A13: 7 | B13: 22WH1A05D6 | C13: DATLA NEHA | E13: 39 | F13: 22WH1A05G8 | G13: SHAIK MULLA AYESHA BANU
A14: 8 | B14: 22WH1A05D7 | C14: KONKA VEDA SREE | E14: 40 | F14: 22WH1A05G9 | G14: MAJETY VENKATA SRAVYA
A15: 9 | B15: 22WH1A05D8 | C15: FARHANA TABASSUM | E15: 41 | F15: 22WH1A05H0 | G15: THATHA RICHITHA
A16: 10 | B16: 22WH1A05D9 | C16: MEKALA SREE SANVIKA | E16: 42 | F16: 22WH1A05H1 | G16: KONDAPATURU GAYATRI
A17: 11 | B17: 22WH1A05E0 | C17: KURUVA AKSHARA BHAVITHA | E17: 43 | F17: 22WH1A05H2 | G17: GADIRAJU RISHITHA
A18: 12 | B18: 22WH1A05E1 | C18: MADDELA RAVALI PATEL | E18: 44 | F18: 22WH1A05H3 | G18: THADA JYOTHIRMAI
... A45: 67 | B45: 23WH5A0515 | C45: JANGILI AKSHAYA | E45: 70 | F45: 23WH5A0518 | G45: JADAV RUPALI
E46: 71 | F46: 23WH5A0519 | G46: YEROLLA RUTH MERCY
B52: Examinations Incharge | G52: Principal

Sheet IT A
A1: BVRIT HYDERABAD College of Engineering for Women (WH)
A2: Rajiv Gandhi Nagar, Bachupally, Hyderabad-500090
A3: III B.TECH. I SEM (R22) NOMINAL ROLLS
A4: 2022 BATCH – FOR THE ACADEMIC YEAR 2023-2024
A5: Branch: IT A | G5: Date: 10.08.2024
A6: S.No. | B6: Hall Ticket No. | C6: Name of the Candidate | E6: S.No. | F6: Hall Ticket No. | G6: Name of the Candidate
A7: 1 | B7: 22WH1A1201 | C7: YARRAMSETTI SUSMITHA | E7: 34 | F7: 22WH1A1234 | G7: GUMMADI SWETHA
A8: 2 | B8: 22WH1A1202 | C8: ADE NIKHITHA | E8: 35 | F8: 22WH1A1235 | G8: CHALLA ROSHIKA
A9: 3 | B9: 22WH1A1203 | C9: ALLURI JANANI SAHASRA | E9: 36 | F9: 22WH1A1236 | G9: POTHU CHANDANA
A10: 4 | B10: 22WH1A1204 | C10: NAGISETTY VENKATA NAGA SATWIKA | E10: 37 | F10: 22WH1A1237 | G10: SHAIK TEHAZEEB SULTHANA
A11: 5 | B11: 22WH1A1205 | C11: TEJAVATH BHAVANA SAKSENA | E11: 38 | F11: 22WH1A1238 | G11: AGRRAPU DURGA BHAVANI
A12: 6 | B12: 22WH1A1206 | C12: JAVVAJI SIVANI | E12: 39 | F12: 22WH1A1239 | G12: KOLLURU SUKRUTHA
A13: 7 | B13: 22WH1A1207 | C13: SNEHA TANGTUR | E13: 40 | F13: 22WH1A1240 | G13: N SRIYA
A14: 8 | B14: 22WH1A1208 | C14: MEDA PAVANI | E14: 41 | F14: 22WH1A1241 | G14: SHAIK SHIRIN
A15: 9 | B15: 22WH1A1209 | C15: P.CHANDRA LEKHA | E15: 42 | F15: 22WH1A1242 | G15: ANJUM AFREEN SYEDA
A16: 10 | B16: 22WH1A1210 | C16: B V R BHAVANA | E16: 43 | F16: 22WH1A1243 | G16: ALETI SRI HARSHINI
A17: 11 | B17: 22WH1A1211 | C17: MUDAVATH ASHWINI | E17: 44 | F17: 22WH1A1244 | G17: TENALI NANDINI
A18: 12 | B18: 22WH1A1212 | C18: PERICHERLA SHRIYA | E18: 45 | F18: 22WH1A1245 | G18: GANDHARI LAHARIKA
... A38: 32 | B38: 22WH1A1232 | C38: KUDALA SHARON | E38: 65 | F38: 22WH1A1265 | G38: KAMBAM SIRI SANJANA
A39: 33 | B39: 22WH1A1233 | C39: SHRADDHA S KAMATH
A43: 66 | B43: 23WH5A1202 | C43: MUDUJUTLA SOWMYA | E43: 69 | F43: 23WH5A1205 | G43: VANAPARTHI BINDHU
A44: 67 | B44: 23WH5A1203 | C44: GOLLAPELLY RISHWITHA | E44: 70 | F44: 23WH5A1206 | G44: BOJJA SRIJA
A45: 68 | B45: 23WH5A1204 | C45: DONTHIREDDY ARCHANA
B48: 23WH5A1201 Detained in II-II due to shortage of attendance for the A.Y. 2023-24
B53: Examinations Incharge | G53: Principal

Sheet IT B
A1: BVRIT HYDERABAD College of Engineering for Women (WH)
A2: Rajiv Gandhi Nagar, Bachupally, Hyderabad-500090
A3: III B.TECH. I SEM (R22) NOMINAL ROLLS
A4: 2022 BATCH – FOR THE ACADEMIC YEAR 2023-2024
A5: Branch: IT B | G5: Date: 10.08.2024
A6: S.No. | B6: Hall Ticket No. | C6: Name of the Candidate | E6: S.No. | F6: Hall Ticket No. | G6: Name of the Candidate
A7: 1 | B7: 21WH1A1271 | C7: K JAHNAVI | E7: 33 | F7: 22WH1A1298 | G7: BUKKALA ANITHA
A8: 2 | B8: 22WH1A1266 | C8: SESHADRI BHARATHI DEVI | E8: 34 | F8: 22WH1A1299 | G8: DHARMAPURAM CHAKRIKA SAI
A9: 3 | B9: 22WH1A1267 | C9: KAREMPUDI SRIHITA | E9: 35 | F9: 22WH1A12A0 | G9: RABIYA WARSI
A10: 4 | B10: 22WH1A1268 | C10: SUNKARA SHANMUKHI | E10: 36 | F10: 22WH1A12A1 | G10: GOGIREDDY AMRUTHA
A11: 5 | B11: 22WH1A1269 | C11: GADDAM BHAVYA SRI | E11: 37 | F11: 22WH1A12A2 | G11: RENEE MANOHARA BETHAPUDY
A12: 6 | B12: 22WH1A1271 | C12: BHUPATHIRAJU VAHINI | E12: 38 | F12: 22WH1A12A3 | G12: VISWANADHAPALLI BHANU SRI
A13: 7 | B13: 22WH1A1272 | C13: LABALA LAXMI VARSHITHA | E13: 39 | F13: 22WH1A12A4 | G13: MUDUNURI AKULLA
A14: 8 | B14: 22WH1A1273 | C14: GUGULOTHU BINDU | E14: 40 | F14: 22WH1A12A5 | G14: KEERTHANA CHOWDARY MANAM
A15: 9 | B15: 22WH1A1274 | C15: GEEDIGINJALA ANKITHA | E15: 41 | F15: 22WH1A12A6 | G15: KAVALI NISSI AMULYA
A16: 10 | B16: 22WH1A1275 | C16: ANAMITRA JOSHI | E16: 42 | F16: 22WH1A12A7 | G16: SAI MEENAKSHI
A17: 11 | B17: 22WH1A1276 | C17: GUJJA BINDHU | E17: 43 | F17: 22WH1A12A8 | G17: KANDURI KRISHNAPRIYA
A18: 12 | B18: 22WH1A1277 | C18: VITSAVAYI SUHITHA | E18: 44 | F18: 22WH1A12A9 | G18: KASHVI CHINTA
... A45: 67 | B45: 23WH5A1209 | C45: SHAIK NAGASRI | E45: 70 | F45: 23WH5A1212 | G45: BOLLOJU SAI LAKSHMI PRAVALLIKA
E46: 71 | F46: 23WH5A1213 | G46: KONADA SHARMILA
B48: Note: | C48: 22WH1A1270 Detained in I-II due to shortage of attendance for the A.Y. 2022-23
C49: 21WH1A1271 Re-Admitted in II-I for the A.Y. 2023-24
B53: Examinations Incharge | G53: Principal

Sheet CSE(AI&ML)
A1: BVRIT HYDERABAD College of Engineering for Women (WH)
A2: Rajiv Gandhi Nagar, Bachupally, Hyderabad-500090
A3: III B.TECH. I SEM (R22) NOMINAL ROLLS
A4: 2022 BATCH – FOR THE ACADEMIC YEAR 2023-2024
A5: Branch: CSE(AI&ML) | G5: Date: 10.08.2024
A6: S.No. | B6: Hall Ticket No. | C6: Name of the Candidate | E6: S.No. | F6: Hall Ticket No. | G6: Name of the Candidate
A7: 1 | B7: 22WH1A6601 | C7: GADE NIKHITA REDDY | E7: 33 | F7: 22WH1A6633 | G7: PASALA PREETHI
A8: 2 | B8: 22WH1A6602 | C8: VODAPALLY HARSHITHA | E8: 34 | F8: 22WH1A6634 | G8: LANDU LASYA
A9: 3 | B9: 22WH1A6603 | C9: DATLA MEGANA LAXMI | E9: 35 | F9: 22WH1A6635 | G9: NELA JIJNASA
A10: 4 | B10: 22WH1A6604 | C10: KOMATI REDDY SNEHAREDDY | E10: 36 | F10: 22WH1A6636 | G10: BOPPANA HEMANYA SAI
A11: 5 | B11: 22WH1A6605 | C11: SADIYA TARANNUM | E11: 37 | F11: 22WH1A6637 | G11: ESHWAROJU LAHARI
A12: 6 | B12: 22WH1A6606 | C12: G.REVATHI SAI NAGESWARI | E12: 38 | F12: 22WH1A6638 | G12: AKKA PRASHANTHI
A13: 7 | B13: 22WH1A6607 | C13: YASHASWINY SRIPADA | E13: 39 | F13: 22WH1A6639 | G13: PERUGU JAHNAVI
A14: 8 | B14: 22WH1A6608 | C14: GEDDA TEJASWINI | E14: 40 | F14: 22WH1A6640 | G14: JAHNVI KAKKAR
A15: 9 | B15: 22WH1A6609 | C15: RAVULAPENTA ISHWARYA | E15: 41 | F15: 22WH1A6641 | G15: GOLLA ANUSHA
A16: 10 | B16: 22WH1A6610 | C16: LANKELA SHARANYA | E16: 42 | F16: 22WH1A6642 | G16: BACHUPALLY NIVEDA
A17: 11 | B17: 22WH1A6611 | C17: KANIGIRI DEVIKA | E17: 43 | F17: 22WH1A6643 | G17: NALI PRASANNA
A18: 12 | B18: 22WH1A6612 | C18: L.VARSHA | E18: 44 | F18: 22WH1A6644 | G18: S AISHWARYA
... A45: 67 | B45: 23WH5A6603 | C45: POTUKUCHI SNEHA | E45: 70 | F45: 23WH5A6606 | G45: PEDDAPURAM SUSHMA
E46: 71 | F46: 23WH5A6607 | G46: TANEERU RAJESHWARI
B52: Examinations Incharge | G52: Principal

Sheet Temp
B2: ='CSE(AI&ML)'!B7 -> 22WH1A6601 | C2: ='CSE(AI&ML)'!F7 -> 22WH1A6633
B3: ='CSE(AI&ML)'!B8 -> 22WH1A6602 | C3: ='CSE(AI&ML)'!F8 -> 22WH1A6634 | J3: {=_xlfn.TOCOL(B2:C38)} -> 22WH1A6601 | L3: =B2 -> 22WH1A6601 | M3: =LOWER(L3) -> 22wh1a6601 | N3: bvrithyderabad.edu.in | O3: =_xlfn.CONCAT(M3,"@",N3) -> 22wh1a6601@bvrithyderabad.edu.in
B4: ='CSE(AI&ML)'!B9 -> 22WH1A6603 | C4: ='CSE(AI&ML)'!F9 -> 22WH1A6635 | J4: 22WH1A6633 | L4: =B3 -> 22WH1A6602 | M4: =LOWER(L4) -> 22wh1a6602 | N4: bvrithyderabad.edu.in | O4: =_xlfn.CONCAT(M4,"@",N4) -> 22wh1a6602@bvrithyderabad.edu.in
B5: ='CSE(AI&ML)'!B10 -> 22WH1A6604 | C5: ='CSE(AI&ML)'!F10 -> 22WH1A6636 | J5: 22WH1A6602 | L5: =B4 -> 22WH1A6603 | M5: =LOWER(L5) -> 22wh1a6603 | N5: bvrithyderabad.edu.in | O5: =_xlfn.CONCAT(M5,"@",N5) -> 22wh1a6603@bvrithyderabad.edu.in
B6: ='CSE(AI&ML)'!B11 -> 22WH1A6605 | C6: ='CSE(AI&ML)'!F11 -> 22WH1A6637 | J6: 22WH1A6634 | L6: =B5 -> 22WH1A6604 | M6: =LOWER(L6) -> 22wh1a6604 | N6: bvrithyderabad.edu.in | O6: =_xlfn.CONCAT(M6,"@",N6) -> 22wh1a6604@bvrithyderabad.edu.in
B7: ='CSE(AI&ML)'!B12 -> 22WH1A6606 | C7: ='CSE(AI&ML)'!F12 -> 22WH1A6638 | J7: 22WH1A6603 | L7: =B6 -> 22WH1A6605 | M7: =LOWER(L7) -> 22wh1a6605 | N7: bvrithyderabad.edu.in | O7: =_xlfn.CONCAT(M7,"@",N7) -> 22wh1a6605@bvrithyderabad.edu.in
B8: ='CSE(AI&ML)'!B13 -> 22WH1A6607 | C8: ='CSE(AI&ML)'!F13 -> 22WH1A6639 | J8: 22WH1A6635 | L8: =B7 -> 22WH1A6606 | M8: =LOWER(L8) -> 22wh1a6606 | N8: bvrithyderabad.edu.in | O8: =_xlfn.CONCAT(M8,"@",N8) -> 22wh1a6606@bvrithyderabad.edu.in
B9: ='CSE(AI&ML)'!B14 -> 22WH1A6608 | C9: ='CSE(AI&ML)'!F14 -> 22WH1A6640 | J9: 22WH1A6604 | L9: =B8 -> 22WH1A6607 | M9: =LOWER(L9) -> 22wh1a6607 | N9: bvrithyderabad.edu.in | O9: =_xlfn.CONCAT(M9,"@",N9) -> 22wh1a6607@bvrithyderabad.edu.in
B10: ='CSE(AI&ML)'!B15 -> 22WH1A6609 | C10: ='CSE(AI&ML)'!F15 -> 22WH1A6641 | J10: 22WH1A6636 | L10: =B9 -> 22WH1A6608 | M10: =LOWER(L10) -> 22wh1a6608 | N10: bvrithyderabad.edu.in | O10: =_xlfn.CONCAT(M10,"@",N10) -> 22wh1a6608@bvrithyderabad.edu.in
B11: ='CSE(AI&ML)'!B16 -> 22WH1A6610 | C11: ='CSE(AI&ML)'!F16 -> 22WH1A6642 | J11: 22WH1A6605 | L11: =B10 -> 22WH1A6609 | M11: =LOWER(L11) -> 22wh1a6609 | N11: bvrithyderabad.edu.in | O11: =_xlfn.CONCAT(M11,"@",N11) -> 22wh1a6609@bvrithyderabad.edu.in
B12: ='CSE(AI&ML)'!B17 -> 22WH1A6611 | C12: ='CSE(AI&ML)'!F17 -> 22WH1A6643 | J12: 22WH1A6637 | L12: =B11 -> 22WH1A6610 | M12: =LOWER(L12) -> 22wh1a6610 | N12: bvrithyderabad.edu.in | O12: =_xlfn.CONCAT(M12,"@",N12) -> 22wh1a6610@bvrithyderabad.edu.in
B13: ='CSE(AI&ML)'!B18 -> 22WH1A6612 | C13: ='CSE(AI&ML)'!F18 -> 22WH1A6644 | J13: 22WH1A6606 | L13: =B12 -> 22WH1A6611 | M13: =LOWER(L13) -> 22wh1a6611 | N13: bvrithyderabad.edu.in | O13: =_xlfn.CONCAT(M13,"@",N13) -> 22wh1a6611@bvrithyderabad.edu.in
B14: ='CSE(AI&ML)'!B19 -> 22WH1A6613 | C14: ='CSE(AI&ML)'!F19 -> 22WH1A6645 | J14: 22WH1A6638 | L14: =B13 -> 22WH1A6612 | M14: =LOWER(L14) -> 22wh1a6612 | N14: bvrithyderabad.edu.in | O14: =_xlfn.CONCAT(M14,"@",N14) -> 22wh1a6612@bvrithyderabad.edu.in
B15: ='CSE(AI&ML)'!B20 -> 22WH1A6614 | C15: ='CSE(AI&ML)'!F20 -> 22WH1A6646 | J15: 22WH1A6607 | L15: =B14 -> 22WH1A6613 | M15: =LOWER(L15) -> 22wh1a6613 | N15: bvrithyderabad.edu.in | O15: =_xlfn.CONCAT(M15,"@",N15) -> 22wh1a6613@bvrithyderabad.edu.in
... B34: ='CSE(AI&ML)'!B39 -> 0 | C34: ='CSE(AI&ML)'!F39 -> 0 | J34: 22WH1A6648 | L34: =B33 -> 22WH1A6632 | M34: =LOWER(L34) -> 22wh1a6632 | N34: bvrithyderabad.edu.in | O34: =_xlfn.CONCAT(M34,"@",N34) -> 22wh1a6632@bvrithyderabad.edu.in
B35: ='CSE(AI&ML)'!B40 -> 0 | C35: ='CSE(AI&ML)'!F40 -> 0 | J35: 22WH1A6617 | L35: =B38 -> 23WH5A6601 | M35: =LOWER(L35) -> 23wh5a6601 | N35: bvrithyderabad.edu.in | O35: =_xlfn.CONCAT(M35,"@",N35) -> 23wh5a6601@bvrithyderabad.edu.in
B36: ='CSE(AI&ML)'!B41 -> 0 | C36: ='CSE(AI&ML)'!F41 -> 0 | J36: 22WH1A6649 | L36: =B39 -> 23WH5A6602 | M36: =LOWER(L36) -> 23wh5a6602 | N36: bvrithyderabad.edu.in | O36: =_xlfn.CONCAT(M36,"@",N36) -> 23wh5a6602@bvrithyderabad.edu.in
B37: ='CSE(AI&ML)'!B42 -> 0 | C37: ='CSE(AI&ML)'!F42 -> 0 | J37: 22WH1A6618 | L37: =B40 -> 23WH5A6603 | M37: =LOWER(L37) -> 23wh5a6603 | N37: bvrithyderabad.edu.in | O37: =_xlfn.CONCAT(M37,"@",N37) -> 23wh5a6603@bvrithyderabad.edu.in
B38: ='CSE(AI&ML)'!B43 -> 23WH5A6601 | C38: ='CSE(AI&ML)'!F43 -> 23WH5A6604 | J38: 22WH1A6650 | L38: =C2 -> 22WH1A6633 | M38: =LOWER(L38) -> 22wh1a6633 | N38: bvrithyderabad.edu.in | O38: =_xlfn.CONCAT(M38,"@",N38) -> 22wh1a6633@bvrithyderabad.edu.in
B39: ='CSE(AI&ML)'!B44 -> 23WH5A6602 | C39: ='CSE(AI&ML)'!F44 -> 23WH5A6605 | J39: 22WH1A6619 | L39: =C3 -> 22WH1A6634 | M39: =LOWER(L39) -> 22wh1a6634 | N39: bvrithyderabad.edu.in | O39: =_xlfn.CONCAT(M39,"@",N39) -> 22wh1a6634@bvrithyderabad.edu.in
B40: ='CSE(AI&ML)'!B45 -> 23WH5A6603 | C40: ='CSE(AI&ML)'!F45 -> 23WH5A6606 | J40: 22WH1A6651 | L40: =C4 -> 22WH1A6635 | M40: =LOWER(L40) -> 22wh1a6635 | N40: bvrithyderabad.edu.in | O40: =_xlfn.CONCAT(M40,"@",N40) -> 22wh1a6635@bvrithyderabad.edu.in
B41: ='CSE(AI&ML)'!B46 -> 0 | C41: ='CSE(AI&ML)'!F46 -> 23WH5A6607 | J41: 22WH1A6620 | L41: =C5 -> 22WH1A6636 | M41: =LOWER(L41) -> 22wh1a6636 | N41: bvrithyderabad.edu.in | O41: =_xlfn.CONCAT(M41,"@",N41) -> 22wh1a6636@bvrithyderabad.edu.in
B42: ='CSE(AI&ML)'!B47 -> 0 | J42: 22WH1A6652 | L42: =C6 -> 22WH1A6637 | M42: =LOWER(L42) -> 22wh1a6637 | N42: bvrithyderabad.edu.in | O42: =_xlfn.CONCAT(M42,"@",N42) -> 22wh1a6637@bvrithyderabad.edu.in
J43: 22WH1A6621 | L43: =C7 -> 22WH1A6638 | M43: =LOWER(L43) -> 22wh1a6638 | N43: bvrithyderabad.edu.in | O43: =_xlfn.CONCAT(M43,"@",N43) -> 22wh1a6638@bvrithyderabad.edu.in
B44: ='IT A'!B49 -> 0 | J44: 22WH1A6653 | L44: =C8 -> 22WH1A6639 | M44: =LOWER(L44) -> 22wh1a6639 | N44: bvrithyderabad.edu.in | O44: =_xlfn.CONCAT(M44,"@",N44) -> 22wh1a6639@bvrithyderabad.edu.in
B45: ='IT A'!B50 -> 0 | J45: 22WH1A6622 | L45: =C9 -> 22WH1A6640 | M45: =LOWER(L45) -> 22wh1a6640 | N45: bvrithyderabad.edu.in | O45: =_xlfn.CONCAT(M45,"@",N45) -> 22wh1a6640@bvrithyderabad.edu.in
J46: 22WH1A6654 | L46: =C10 -> 22WH1A6641 | M46: =LOWER(L46) -> 22wh1a6641 | N46: bvrithyderabad.edu.in | O46: =_xlfn.CONCAT(M46,"@",N46) -> 22wh1a6641@bvrithyderabad.edu.in
J47: 22WH1A6623 | L47: =C11 -> 22WH1A6642 | M47: =LOWER(L47) -> 22wh1a6642 | N47: bvrithyderabad.edu.in | O47: =_xlfn.CONCAT(M47,"@",N47) -> 22wh1a6642@bvrithyderabad.edu.in
J48: 22WH1A6655 | L48: =C12 -> 22WH1A6643 | M48: =LOWER(L48) -> 22wh1a6643 | N48: bvrithyderabad.edu.in | O48: =_xlfn.CONCAT(M48,"@",N48) -> 22wh1a6643@bvrithyderabad.edu.in
J49: 22WH1A6624 | L49: =C13 -> 22WH1A6644 | M49: =LOWER(L49) -> 22wh1a6644 | N49: bvrithyderabad.edu.in | O49: =_xlfn.CONCAT(M49,"@",N49) -> 22wh1a6644@bvrithyderabad.edu.in
J50: 22WH1A6656 | L50: =C14 -> 22WH1A6645 | M50: =LOWER(L50) -> 22wh1a6645 | N50: bvrithyderabad.edu.in | O50: =_xlfn.CONCAT(M50,"@",N50) -> 22wh1a6645@bvrithyderabad.edu.in
J51: 22WH1A6625 | L51: =C15 -> 22WH1A6646 | M51: =LOWER(L51) -> 22wh1a6646 | N51: bvrithyderabad.edu.in | O51: =_xlfn.CONCAT(M51,"@",N51) -> 22wh1a6646@bvrithyderabad.edu.in
J52: 22WH1A6657 | L52: =C16 -> 22WH1A6647 | M52: =LOWER(L52) -> 22wh1a6647 | N52: bvrithyderabad.edu.in | O52: =_xlfn.CONCAT(M52,"@",N52) -> 22wh1a6647@bvrithyderabad.edu.in
J53: 22WH1A6626 | L53: =C17 -> 22WH1A6648 | M53: =LOWER(L53) -> 22wh1a6648 | N53: bvrithyderabad.edu.in | O53: =_xlfn.CONCAT(M53,"@",N53) -> 22wh1a6648@bvrithyderabad.edu.in
J54: 22WH1A6658 | L54: =C18 -> 22WH1A6649 | M54: =LOWER(L54) -> 22wh1a6649 | N54: bvrithyderabad.edu.in | O54: =_xlfn.CONCAT(M54,"@",N54) -> 22wh1a6649@bvrithyderabad.edu.in
J55: 22WH1A6627 | L55: =C19 -> 22WH1A6650 | M55: =LOWER(L55) -> 22wh1a6650 | N55: bvrithyderabad.edu.in | O55: =_xlfn.CONCAT(M55,"@",N55) -> 22wh1a6650@bvrithyderabad.edu.in
J56: 22WH1A6659 | L56: =C20 -> 22WH1A6651 | M56: =LOWER(L56) -> 22wh1a6651 | N56: bvrithyderabad.edu.in | O56: =_xlfn.CONCAT(M56,"@",N56) -> 22wh1a6651@bvrithyderabad.edu.in
J57: 22WH1A6628 | L57: =C21 -> 22WH1A6652 | M57: =LOWER(L57) -> 22wh1a6652 | N57: bvrithyderabad.edu.in | O57: =_xlfn.CONCAT(M57,"@",N57) -> 22wh1a6652@bvrithyderabad.edu.in
... J66: 22WH1A6664 | L66: =C30 -> 22WH1A6661 | M66: =LOWER(L66) -> 22wh1a6661 | N66: bvrithyderabad.edu.in | O66: =_xlfn.CONCAT(M66,"@",N66) -> 22wh1a6661@bvrithyderabad.edu.in
J67: 0 | L67: =C31 -> 22WH1A6662 | M67: =LOWER(L67) -> 22wh1a6662 | N67: bvrithyderabad.edu.in | O67: =_xlfn.CONCAT(M67,"@",N67) -> 22wh1a6662@bvrithyderabad.edu.in
...

Sheet CSE(AI&ML) Mail List
A1: 22wh1a6601@bvrithyderabad.edu.in
A2: 22wh1a6602@bvrithyderabad.edu.in
A3: 22wh1a6603@bvrithyderabad.edu.in
A4: 22wh1a6604@bvrithyderabad.edu.in
A5: 22wh1a6605@bvrithyderabad.edu.in
A6: 22wh1a6606@bvrithyderabad.edu.in
A7: 22wh1a6607@bvrithyderabad.edu.in
A8: 22wh1a6608@bvrithyderabad.edu.in
A9: 22wh1a6609@bvrithyderabad.edu.in
A10: 22wh1a6610@bvrithyderabad.edu.in
A11: 22wh1a6611@bvrithyderabad.edu.in
A12: 22wh1a6612@bvrithyderabad.edu.in
... A71: 23wh5a6606@bvrithyderabad.edu.in

Sheet IT Mail List
A1: 22wh1a1201@bvrithyderabad.edu.in
A2: 22wh1a1202@bvrithyderabad.edu.in
A3: 22wh1a1203@bvrithyderabad.edu.in
A4: 22wh1a1204@bvrithyderabad.edu.in
A5: 22wh1a1205@bvrithyderabad.edu.in
A6: 22wh1a1206@bvrithyderabad.edu.in
A7: 22wh1a1207@bvrithyderabad.edu.in
A8: 22wh1a1208@bvrithyderabad.edu.in
A9: 22wh1a1209@bvrithyderabad.edu.in
A10: 22wh1a1210@bvrithyderabad.edu.in
A11: 22wh1a1211@bvrithyderabad.edu.in
A12: 22wh1a1212@bvrithyderabad.edu.in
... A139: 23wh5a1212@bvrithyderabad.edu.in

Sheet EEE Mail List
A1: 22wh1a0201@bvrithyderabad.edu.in
A2: 22wh1a0202@bvrithyderabad.edu.in
A3: 22wh1a0203@bvrithyderabad.edu.in
A4: 22wh1a0204@bvrithyderabad.edu.in
A5: 22wh1a0205@bvrithyderabad.edu.in
A6: 22wh1a0206@bvrithyderabad.edu.in
A7: 22wh1a0207@bvrithyderabad.edu.in
A8: 22wh1a0208@bvrithyderabad.edu.in
A9: 22wh1a0209@bvrithyderabad.edu.in
A10: 22wh1a0210@bvrithyderabad.edu.in
A11: 22wh1a0211@bvrithyderabad.edu.in
A12: 22wh1a0212@bvrithyderabad.edu.in
... A69: 23wh5a0221@bvrithyderabad.edu.in

Sheet ECE Mail List
A1: 21wh1a0483@bvrithyderabad.edu.in
A2: 22wh1a0401@bvrithyderabad.edu.in
A3: 22wh1a0402@bvrithyderabad.edu.in
A4: 22wh1a0403@bvrithyderabad.edu.in
A5: 22wh1a0404@bvrithyderabad.edu.in
A6: 22wh1a0405@bvrithyderabad.edu.in
A7: 22wh1a0406@bvrithyderabad.edu.in
A8: 22wh1a0407@bvrithyderabad.edu.in
A9: 22wh1a0408@bvrithyderabad.edu.in
A10: 22wh1a0409@bvrithyderabad.edu.in
A11: 22wh1a0410@bvrithyderabad.edu.in
A12: 22wh1a0411@bvrithyderabad.edu.in
... A137: 23wh5a0412@bvrithyderabad.edu.in

Sheet CSE Mail List
A1: 22WH1A0501@bvrithyderabad.edu.in
A2: 22WH1A0502@bvrithyderabad.edu.in
A3: 22WH1A0503@bvrithyderabad.edu.in
A4: 22WH1A0504@bvrithyderabad.edu.in
A5: 22WH1A0505@bvrithyderabad.edu.in | J5: 22WH1A0501@bvrithyderabad.edu.in
A6: 22WH1A0506@bvrithyderabad.edu.in | J6: 22WH1A0502@bvrithyderabad.edu.in
A7: 22WH1A0507@bvrithyderabad.edu.in | J7: 22WH1A0503@bvrithyderabad.edu.in
A8: 22WH1A0508@bvrithyderabad.edu.in | J8: 22WH1A0504@bvrithyderabad.edu.in
A9: 22WH1A0509@bvrithyderabad.edu.in | J9: 22WH1A0505@bvrithyderabad.edu.in
A10: 22WH1A0510@bvrithyderabad.edu.in | J10: 22WH1A0506@bvrithyderabad.edu.in
A11: 22WH1A0511@bvrithyderabad.edu.in | J11: 22WH1A0507@bvrithyderabad.edu.in
A12: 22WH1A0512@bvrithyderabad.edu.in | J12: 22WH1A0508@bvrithyderabad.edu.in
A13: 22WH1A0513@bvrithyderabad.edu.in | J13: 22WH1A0509@bvrithyderabad.edu.in
A14: 22WH1A0514@bvrithyderabad.edu.in | J14: 22WH1A0510@bvrithyderabad.edu.in
A15: 22WH1A0515@bvrithyderabad.edu.in | J15: 22WH1A0511@bvrithyderabad.edu.in
A16: 22WH1A0516@bvrithyderabad.edu.in | J16: 22WH1A0512@bvrithyderabad.edu.in
... A75: 22WH1A0575@bvrithyderabad.edu.in | J75: 23WH5A0506@bvrithyderabad.edu.in
A76: 22WH1A0577@bvrithyderabad.edu.in
A77: 22WH1A0578@bvrithyderabad.edu.in
A78: 22WH1A0579@bvrithyderabad.edu.in
A79: 22WH1A0580@bvrithyderabad.edu.in
A80: 22WH1A0581@bvrithyderabad.edu.in
A81: 22WH1A0582@bvrithyderabad.edu.in
A82: 22WH1A0583@bvrithyderabad.edu.in
A83: 22WH1A0584@bvrithyderabad.edu.in
A84: 22WH1A0585@bvrithyderabad.edu.in
A85: 22WH1A0586@bvrithyderabad.edu.in
A86: 22WH1A0587@bvrithyderabad.edu.in
A87: 22WH1A0588@bvrithyderabad.edu.in
... A210: 23WH5A0519@bvrithyderabad.edu.in
